<sdf version='1.9'>
  <model name='myCobot_280_PI_230708'>
    <link name='base_link'>
      <inertial>
        <pose>0.002747322897255657 0.006582295750339679 0.04742985622407555 0 0 0</pose>
        <mass>0.62308159439402777</mass>
        <inertia>
          <ixx>0.00068400000000000004</ixx>
          <ixy>-3.0000000000000001e-06</ixy>
          <ixz>3.0000000000000001e-06</ixz>
          <iyy>0.00052899999999999996</iyy>
          <iyz>5.0000000000000004e-06</iyz>
          <izz>0.00097400000000000004</izz>
        </inertia>
      </inertial>
      <collision name='base_link_collision'>
        <pose>0 0 0 0 0 0</pose>
        <geometry>
          <mesh>
            <scale>0.001 0.001 0.001</scale>
            <uri>model://warehouse/meshes/base_link.stl</uri>
          </mesh>
        </geometry>
        <surface>
          <contact>
            <ode/>
          </contact>
          <friction>
            <ode>
              <mu>0.20000000000000001</mu>
              <mu2>0.20000000000000001</mu2>
            </ode>
          </friction>
        </surface>
      </collision>
      <visual name='base_link_visual'>
        <pose>0 0 0 0 0 0</pose>
        <geometry>
          <mesh>
            <scale>0.001 0.001 0.001</scale>
            <uri>model://warehouse/meshes/base_link.stl</uri>
          </mesh>
        </geometry>
        <material>
          <script>
            <name>Gazebo/Silver</name>
            <uri>file://media/materials/scripts/gazebo.material</uri>
          </script>
          <diffuse>0.875 0.875 0.875 1</diffuse>
          <ambient>0.875 0.875 0.875 1</ambient>
        </material>
      </visual>
      <self_collide>true</self_collide>
      <gravity>true</gravity>
    </link>
    <joint name='Revolute 11' type='revolute'>
      <pose relative_to='base_link'>0.002418 0 0.072835 0 0 0</pose>
      <parent>base_link</parent>
      <child>j1_1</child>
      <axis>
        <xyz>0 0 1</xyz>
        <limit>
          <lower>-10000000000000000</lower>
          <upper>10000000000000000</upper>
        </limit>
        <dynamics>
          <spring_reference>0</spring_reference>
          <spring_stiffness>0</spring_stiffness>
        </dynamics>
      </axis>
    </joint>
    <link name='j1_1'>
      <pose relative_to='Revolute 11'>0 0 0 0 0 0</pose>
      <inertial>
        <pose>-0.007149892775153005 6.361148928414971e-06 0.03826778333473511 0 0 0</pose>
        <mass>0.33558054499825191</mass>
        <inertia>
          <ixx>0.00031700000000000001</ixx>
          <ixy>0</ixy>
          <ixz>5.5999999999999999e-05</ixz>
          <iyy>0.000357</iyy>
          <iyz>0</iyz>
          <izz>0.000183</izz>
        </inertia>
      </inertial>
      <collision name='j1_1_collision'>
        <pose>-0.002418 0 -0.072835 0 0 0</pose>
        <geometry>
          <mesh>
            <scale>0.001 0.001 0.001</scale>
            <uri>model://warehouse/meshes/j1_1.stl</uri>
          </mesh>
        </geometry>
        <surface>
          <contact>
            <ode/>
          </contact>
          <friction>
            <ode>
              <mu>0.20000000000000001</mu>
              <mu2>0.20000000000000001</mu2>
            </ode>
          </friction>
        </surface>
      </collision>
      <visual name='j1_1_visual'>
        <pose>-0.002418 0 -0.072835 0 0 0</pose>
        <geometry>
          <mesh>
            <scale>0.001 0.001 0.001</scale>
            <uri>model://warehouse/meshes/j1_1.stl</uri>
          </mesh>
        </geometry>
        <material>
          <script>
            <name>Gazebo/Silver</name>
            <uri>file://media/materials/scripts/gazebo.material</uri>
          </script>
          <diffuse>0.875 0.875 0.875 1</diffuse>
          <ambient>0.875 0.875 0.875 1</ambient>
        </material>
      </visual>
      <self_collide>true</self_collide>
    </link>
    <joint name='Revolute 4' type='revolute'>
      <pose relative_to='j1_1'>-0.034705 0 0.059705 0 0 0</pose>
      <parent>j1_1</parent>
      <child>j2_1</child>
      <axis>
        <xyz>1 0 0</xyz>
        <limit>
          <lower>-10000000000000000</lower>
          <upper>10000000000000000</upper>
        </limit>
        <dynamics>
          <spring_reference>0</spring_reference>
          <spring_stiffness>0</spring_stiffness>
        </dynamics>
      </axis>
    </joint>
    <link name='j2_1'>
      <pose relative_to='Revolute 4'>0 0 0 0 0 0</pose>
      <inertial>
        <pose>-0.02320878388235743 -1.163147892022158e-06 0.05161800841280001 0 0 0</pose>
        <mass>0.52455781657165068</mass>
        <inertia>
          <ixx>0.0013110000000000001</ixx>
          <ixy>0</ixy>
          <ixz>-9.9999999999999995e-07</ixz>
          <iyy>0.001359</iyy>
          <iyz>0</iyz>
          <izz>0.00027799999999999998</izz>
        </inertia>
      </inertial>
      <collision name='j2_1_collision'>
        <pose>0.032287 0 -0.13254 0 0 0</pose>
        <geometry>
          <mesh>
            <scale>0.001 0.001 0.001</scale>
            <uri>model://warehouse/meshes/j2_1.stl</uri>
          </mesh>
        </geometry>
        <surface>
          <contact>
            <ode/>
          </contact>
          <friction>
            <ode>
              <mu>0.20000000000000001</mu>
              <mu2>0.20000000000000001</mu2>
            </ode>
          </friction>
        </surface>
      </collision>
      <visual name='j2_1_visual'>
        <pose>0.032287 0 -0.13254 0 0 0</pose>
        <geometry>
          <mesh>
            <scale>0.001 0.001 0.001</scale>
            <uri>model://warehouse/meshes/j2_1.stl</uri>
          </mesh>
        </geometry>
        <material>
          <script>
            <name>Gazebo/Silver</name>
            <uri>file://media/materials/scripts/gazebo.material</uri>
          </script>
          <diffuse>0.875 0.875 0.875 1</diffuse>
          <ambient>0.875 0.875 0.875 1</ambient>
        </material>
      </visual>
      <self_collide>true</self_collide>
    </link>
    <joint name='Revolute 5' type='revolute'>
      <pose relative_to='j2_1'>0.006776 0 0.11 0 0 0</pose>
      <parent>j2_1</parent>
      <child>j3_1</child>
      <axis>
        <xyz>-1 0 0</xyz>
        <limit>
          <lower>-10000000000000000</lower>
          <upper>10000000000000000</upper>
        </limit>
        <dynamics>
          <spring_reference>0</spring_reference>
          <spring_stiffness>0</spring_stiffness>
        </dynamics>
      </axis>
    </joint>
    <link name='j3_1'>
      <pose relative_to='Revolute 5'>0 0 0 0 0 0</pose>
      <inertial>
        <pose>0.02307048913489495 4.936074832724978e-07 0.04319682555036311 0 0 0</pose>
        <mass>0.4153095281616444</mass>
        <inertia>
          <ixx>0.00078299999999999995</ixx>
          <ixy>0</ixy>
          <ixz>-3.4e-05</ixz>
          <iyy>0.000834</iyy>
          <iyz>0</iyz>
          <izz>0.00019100000000000001</izz>
        </inertia>
      </inertial>
      <collision name='j3_1_collision'>
        <pose>0.025511 0 -0.24254 0 0 0</pose>
        <geometry>
          <mesh>
            <scale>0.001 0.001 0.001</scale>
            <uri>model://warehouse/meshes/j3_1.stl</uri>
          </mesh>
        </geometry>
        <surface>
          <contact>
            <ode/>
          </contact>
          <friction>
            <ode>
              <mu>0.20000000000000001</mu>
              <mu2>0.20000000000000001</mu2>
            </ode>
          </friction>
        </surface>
      </collision>
      <visual name='j3_1_visual'>
        <pose>0.025511 0 -0.24254 0 0 0</pose>
        <geometry>
          <mesh>
            <scale>0.001 0.001 0.001</scale>
            <uri>model://warehouse/meshes/j3_1.stl</uri>
          </mesh>
        </geometry>
        <material>
          <script>
            <name>Gazebo/Silver</name>
            <uri>file://media/materials/scripts/gazebo.material</uri>
          </script>
          <diffuse>0.875 0.875 0.875 1</diffuse>
          <ambient>0.875 0.875 0.875 1</ambient>
        </material>
      </visual>
      <self_collide>true</self_collide>
    </link>
    <joint name='Revolute 6' type='revolute'>
      <pose relative_to='j3_1'>-0.001444 0 0.096 0 0 0</pose>
      <parent>j3_1</parent>
      <child>j4_1</child>
      <axis>
        <xyz>1 0 0</xyz>
        <limit>
          <lower>-10000000000000000</lower>
          <upper>10000000000000000</upper>
        </limit>
        <dynamics>
          <spring_reference>0</spring_reference>
          <spring_stiffness>0</spring_stiffness>
        </dynamics>
      </axis>
    </joint>
    <link name='j4_1'>
      <pose relative_to='Revolute 6'>0 0 0 0 0 0</pose>
      <inertial>
        <pose>-0.02273256983701955 -2.652785934165438e-06 0.007678832280468728 0 0 0</pose>
        <mass>0.18901347895586909</mass>
        <inertia>
          <ixx>7.1000000000000005e-05</ixx>
          <ixy>0</ixy>
          <ixz>1.7e-05</ixz>
          <iyy>9.1000000000000003e-05</iyy>
          <iyz>0</iyz>
          <izz>6.8999999999999997e-05</izz>
        </inertia>
      </inertial>
      <collision name='j4_1_collision'>
        <pose>0.026955 0 -0.33854 0 0 0</pose>
        <geometry>
          <mesh>
            <scale>0.001 0.001 0.001</scale>
            <uri>model://warehouse/meshes/j4_1.stl</uri>
          </mesh>
        </geometry>
        <surface>
          <contact>
            <ode/>
          </contact>
          <friction>
            <ode>
              <mu>0.20000000000000001</mu>
              <mu2>0.20000000000000001</mu2>
            </ode>
          </friction>
        </surface>
      </collision>
      <visual name='j4_1_visual'>
        <pose>0.026955 0 -0.33854 0 0 0</pose>
        <geometry>
          <mesh>
            <scale>0.001 0.001 0.001</scale>
            <uri>model://warehouse/meshes/j4_1.stl</uri>
          </mesh>
        </geometry>
        <material>
          <script>
            <name>Gazebo/Silver</name>
            <uri>file://media/materials/scripts/gazebo.material</uri>
          </script>
          <diffuse>0.875 0.875 0.875 1</diffuse>
          <ambient>0.875 0.875 0.875 1</ambient>
        </material>
      </visual>
      <self_collide>true</self_collide>
    </link>
    <joint name='Revolute 7' type='revolute'>
      <pose relative_to='j4_1'>-0.033245 0 0.03483 0 0 0</pose>
      <parent>j4_1</parent>
      <child>j5_1</child>
      <axis>
        <xyz>0 0 1</xyz>
        <limit>
          <lower>-10000000000000000</lower>
          <upper>10000000000000000</upper>
        </limit>
        <dynamics>
          <spring_reference>0</spring_reference>
          <spring_stiffness>0</spring_stiffness>
        </dynamics>
      </axis>
    </joint>
    <link name='j5_1'>
      <pose relative_to='Revolute 7'>0 0 0 0 0 0</pose>
      <inertial>
        <pose>-0.000108081555744835 -0.002886655859362481 0.02764322333823455 0 0 0</pose>
        <mass>0.22647596707372619</mass>
        <inertia>
          <ixx>0.000144</ixx>
          <ixy>0</ixy>
          <ixz>9.9999999999999995e-07</ixz>
          <iyy>0.00011</iyy>
          <iyz>9.0000000000000002e-06</iyz>
          <izz>9.7999999999999997e-05</izz>
        </inertia>
      </inertial>
      <collision name='j5_1_collision'>
        <pose>0.0602 0 -0.37337 0 0 0</pose>
        <geometry>
          <mesh>
            <scale>0.001 0.001 0.001</scale>
            <uri>model://warehouse/meshes/j5_1.stl</uri>
          </mesh>
        </geometry>
        <surface>
          <contact>
            <ode/>
          </contact>
          <friction>
            <ode>
              <mu>0.20000000000000001</mu>
              <mu2>0.20000000000000001</mu2>
            </ode>
          </friction>
        </surface>
      </collision>
      <visual name='j5_1_visual'>
        <pose>0.0602 0 -0.37337 0 0 0</pose>
        <geometry>
          <mesh>
            <scale>0.001 0.001 0.001</scale>
            <uri>model://warehouse/meshes/j5_1.stl</uri>
          </mesh>
        </geometry>
        <material>
          <script>
            <name>Gazebo/Silver</name>
            <uri>file://media/materials/scripts/gazebo.material</uri>
          </script>
          <diffuse>0.875 0.875 0.875 1</diffuse>
          <ambient>0.875 0.875 0.875 1</ambient>
        </material>
      </visual>
      <self_collide>true</self_collide>
    </link>
    <joint name='Revolute 9' type='revolute'>
      <pose relative_to='j5_1'>0 -0.031671 0.039625 0 0 0</pose>
      <parent>j5_1</parent>
      <child>j6_1</child>
      <axis>
        <xyz>0 1 0</xyz>
        <limit>
          <lower>-10000000000000000</lower>
          <upper>10000000000000000</upper>
        </limit>
        <dynamics>
          <spring_reference>0</spring_reference>
          <spring_stiffness>0</spring_stiffness>
        </dynamics>
      </axis>
    </joint>
    <link name='j6_1'>
      <pose relative_to='Revolute 9'>0 0 0 0 0 0</pose>
      <inertial>
        <pose>0.0009815386435483564 -0.04740005647815091 0.00104006728103076 0 0 0</pose>
        <mass>1.0172201224966</mass>
        <inertia>
          <ixx>0.00078362466971651761</ixx>
          <ixy>5.6136205498026533e-07</ixy>
          <ixz>-1.9065955335734011e-05</ixz>
          <iyy>0.00047513214324458098</iyy>
          <iyz>-8.5281956164083876e-05</iyz>
          <izz>0.00096761683314575868</izz>
        </inertia>
      </inertial>
      <collision name='j6_1_collision'>
        <pose>0.0602 0.031671 -0.412995 0 0 0</pose>
        <geometry>
          <mesh>
            <scale>0.001 0.001 0.001</scale>
            <uri>model://warehouse/meshes/j6_1.stl</uri>
          </mesh>
        </geometry>
        <surface>
          <contact>
            <ode/>
          </contact>
          <friction>
            <ode>
              <mu>0.20000000000000001</mu>
              <mu2>0.20000000000000001</mu2>
            </ode>
          </friction>
        </surface>
      </collision>
      <collision name='j6_1_fixed_joint_lump__gripper_1_collision_1'>
        <pose>0.0602 0.031671 -0.412995 0 0 0</pose>
        <geometry>
          <mesh>
            <scale>0.001 0.001 0.001</scale>
            <uri>model://warehouse/meshes/gripper_1.stl</uri>
          </mesh>
        </geometry>
        <surface>
          <contact>
            <ode/>
          </contact>
          <friction>
            <ode>
              <mu>0.20000000000000001</mu>
              <mu2>0.20000000000000001</mu2>
            </ode>
          </friction>
        </surface>
      </collision>
      <visual name='j6_1_visual'>
        <pose>0.0602 0.031671 -0.412995 0 0 0</pose>
        <geometry>
          <mesh>
            <scale>0.001 0.001 0.001</scale>
            <uri>model://warehouse/meshes/j6_1.stl</uri>
          </mesh>
        </geometry>
        <material>
          <script>
            <name>Gazebo/Silver</name>
            <uri>file://media/materials/scripts/gazebo.material</uri>
          </script>
          <diffuse>0.875 0.875 0.875 1</diffuse>
          <ambient>0.875 0.875 0.875 1</ambient>
        </material>
      </visual>
      <visual name='j6_1_fixed_joint_lump__gripper_1_visual_1'>
        <pose>0.0602 0.031671 -0.412995 0 0 0</pose>
        <geometry>
          <mesh>
            <scale>0.001 0.001 0.001</scale>
            <uri>model://warehouse/meshes/gripper_1.stl</uri>
          </mesh>
        </geometry>
        <material>
          <script>
            <name>Gazebo/Silver</name>
            <uri>file://media/materials/scripts/gazebo.material</uri>
          </script>
          <diffuse>0.875 0.875 0.875 1</diffuse>
          <ambient>0.875 0.875 0.875 1</ambient>
        </material>
      </visual>
      <self_collide>true</self_collide>
      <self_collide>true</self_collide>
    </link>
    <frame name='Rigid 13' attached_to='j6_1'>
      <pose>0 -0.013195 0 0 -0 0</pose>
    </frame>
    <frame name='gripper_1' attached_to='Rigid 13'/>
  </model>
</sdf>
