<?xml version="1.0" ?>
<!-- =================================================================================== -->
<!-- |    This document was autogenerated by xacro from src/myCobot_280_PI_230708_description/urdf/myCobot_280_PI_230708.xacro | -->
<!-- |    EDITING THIS FILE BY HAND IS NOT RECOMMENDED                                 | -->
<!-- =================================================================================== -->
<robot name="myCobot_280_PI_230708">
  <material name="silver">
    <color rgba="0.700 0.700 0.700 1.000"/>
  </material>
  <gazebo reference="base_link">
    <material>Gazebo/Silver</material>
    <mu1>0.2</mu1>
    <mu2>0.2</mu2>
    <self_collide>true</self_collide>
    <gravity>true</gravity>
  </gazebo>
  <gazebo reference="j2_1">
    <material>Gazebo/Silver</material>
    <mu1>0.2</mu1>
    <mu2>0.2</mu2>
    <self_collide>true</self_collide>
  </gazebo>
  <gazebo reference="j3_1">
    <material>Gazebo/Silver</material>
    <mu1>0.2</mu1>
    <mu2>0.2</mu2>
    <self_collide>true</self_collide>
  </gazebo>
  <gazebo reference="j4_1">
    <material>Gazebo/Silver</material>
    <mu1>0.2</mu1>
    <mu2>0.2</mu2>
    <self_collide>true</self_collide>
  </gazebo>
  <gazebo reference="j5_1">
    <material>Gazebo/Silver</material>
    <mu1>0.2</mu1>
    <mu2>0.2</mu2>
    <self_collide>true</self_collide>
  </gazebo>
  <gazebo reference="j6_1">
    <material>Gazebo/Silver</material>
    <mu1>0.2</mu1>
    <mu2>0.2</mu2>
    <self_collide>true</self_collide>
  </gazebo>
  <gazebo reference="j1_1">
    <material>Gazebo/Silver</material>
    <mu1>0.2</mu1>
    <mu2>0.2</mu2>
    <self_collide>true</self_collide>
  </gazebo>
  <gazebo reference="gripper_1">
    <material>Gazebo/Silver</material>
    <mu1>0.2</mu1>
    <mu2>0.2</mu2>
    <self_collide>true</self_collide>
  </gazebo>
  <link name="base_link">
    <inertial>
      <origin rpy="0 0 0" xyz="0.0027473228972556573 0.006582295750339679 0.04742985622407555"/>
      <mass value="0.6230815943940278"/>
      <inertia ixx="0.000684" ixy="-3e-06" ixz="3e-06" iyy="0.000529" iyz="5e-06" izz="0.000974"/>
    </inertial>
    <visual>
      <origin rpy="0 0 0" xyz="0 0 0"/>
      <geometry>
        <mesh filename="package://warehouse/meshes/base_link.stl" scale="0.001 0.001 0.001"/>
      </geometry>
      <material name="silver"/>
    </visual>
    <collision>
      <origin rpy="0 0 0" xyz="0 0 0"/>
      <geometry>
        <mesh filename="package://warehouse/meshes/base_link.stl" scale="0.001 0.001 0.001"/>
      </geometry>
    </collision>
  </link>
  <link name="j2_1">
    <inertial>
      <origin rpy="0 0 0" xyz="-0.023208783882357434 -1.1631478920221578e-06 0.05161800841280001"/>
      <mass value="0.5245578165716507"/>
      <inertia ixx="0.001311" ixy="0.0" ixz="-1e-06" iyy="0.001359" iyz="-0.0" izz="0.000278"/>
    </inertial>
    <visual>
      <origin rpy="0 0 0" xyz="0.032287 -0.0 -0.13254"/>
      <geometry>
        <mesh filename="package://warehouse/meshes/j2_1.stl" scale="0.001 0.001 0.001"/>
      </geometry>
      <material name="silver"/>
    </visual>
    <collision>
      <origin rpy="0 0 0" xyz="0.032287 -0.0 -0.13254"/>
      <geometry>
        <mesh filename="package://warehouse/meshes/j2_1.stl" scale="0.001 0.001 0.001"/>
      </geometry>
    </collision>
  </link>
  <link name="j3_1">
    <inertial>
      <origin rpy="0 0 0" xyz="0.02307048913489495 4.936074832724978e-07 0.04319682555036311"/>
      <mass value="0.4153095281616444"/>
      <inertia ixx="0.000783" ixy="-0.0" ixz="-3.4e-05" iyy="0.000834" iyz="0.0" izz="0.000191"/>
    </inertial>
    <visual>
      <origin rpy="0 0 0" xyz="0.025511 -0.0 -0.24254"/>
      <geometry>
        <mesh filename="package://warehouse/meshes/j3_1.stl" scale="0.001 0.001 0.001"/>
      </geometry>
      <material name="silver"/>
    </visual>
    <collision>
      <origin rpy="0 0 0" xyz="0.025511 -0.0 -0.24254"/>
      <geometry>
        <mesh filename="package://warehouse/meshes/j3_1.stl" scale="0.001 0.001 0.001"/>
      </geometry>
    </collision>
  </link>
  <link name="j4_1">
    <inertial>
      <origin rpy="0 0 0" xyz="-0.022732569837019552 -2.652785934165438e-06 0.007678832280468728"/>
      <mass value="0.1890134789558691"/>
      <inertia ixx="7.1e-05" ixy="0.0" ixz="1.7e-05" iyy="9.1e-05" iyz="0.0" izz="6.9e-05"/>
    </inertial>
    <visual>
      <origin rpy="0 0 0" xyz="0.026955 -0.0 -0.33854"/>
      <geometry>
        <mesh filename="package://warehouse/meshes/j4_1.stl" scale="0.001 0.001 0.001"/>
      </geometry>
      <material name="silver"/>
    </visual>
    <collision>
      <origin rpy="0 0 0" xyz="0.026955 -0.0 -0.33854"/>
      <geometry>
        <mesh filename="package://warehouse/meshes/j4_1.stl" scale="0.001 0.001 0.001"/>
      </geometry>
    </collision>
  </link>
  <link name="j5_1">
    <inertial>
      <origin rpy="0 0 0" xyz="-0.00010808155574483502 -0.0028866558593624806 0.027643223338234546"/>
      <mass value="0.22647596707372625"/>
      <inertia ixx="0.000144" ixy="0.0" ixz="1e-06" iyy="0.00011" iyz="9e-06" izz="9.8e-05"/>
    </inertial>
    <visual>
      <origin rpy="0 0 0" xyz="0.0602 -0.0 -0.37337"/>
      <geometry>
        <mesh filename="package://warehouse/meshes/j5_1.stl" scale="0.001 0.001 0.001"/>
      </geometry>
      <material name="silver"/>
    </visual>
    <collision>
      <origin rpy="0 0 0" xyz="0.0602 -0.0 -0.37337"/>
      <geometry>
        <mesh filename="package://warehouse/meshes/j5_1.stl" scale="0.001 0.001 0.001"/>
      </geometry>
    </collision>
  </link>
  <link name="j6_1">
    <inertial>
      <origin rpy="0 0 0" xyz="-1.5456861804374888e-06 -0.006886786810611438 -3.1535699260842875e-06"/>
      <mass value="0.060486570976393934"/>
      <inertia ixx="7e-06" ixy="-0.0" ixz="-0.0" iyy="1.1e-05" iyz="0.0" izz="7e-06"/>
    </inertial>
    <visual>
      <origin rpy="0 0 0" xyz="0.0602 0.031671 -0.412995"/>
      <geometry>
        <mesh filename="package://warehouse/meshes/j6_1.stl" scale="0.001 0.001 0.001"/>
      </geometry>
      <material name="silver"/>
    </visual>
    <collision>
      <origin rpy="0 0 0" xyz="0.0602 0.031671 -0.412995"/>
      <geometry>
        <mesh filename="package://warehouse/meshes/j6_1.stl" scale="0.001 0.001 0.001"/>
      </geometry>
    </collision>
  </link>
  <link name="j1_1">
    <inertial>
      <origin rpy="0 0 0" xyz="-0.007149892775153005 6.361148928414971e-06 0.038267783334735114"/>
      <mass value="0.3355805449982519"/>
      <inertia ixx="0.000317" ixy="-0.0" ixz="5.6e-05" iyy="0.000357" iyz="0.0" izz="0.000183"/>
    </inertial>
    <visual>
      <origin rpy="0 0 0" xyz="-0.002418 -0.0 -0.072835"/>
      <geometry>
        <mesh filename="package://warehouse/meshes/j1_1.stl" scale="0.001 0.001 0.001"/>
      </geometry>
      <material name="silver"/>
    </visual>
    <collision>
      <origin rpy="0 0 0" xyz="-0.002418 -0.0 -0.072835"/>
      <geometry>
        <mesh filename="package://warehouse/meshes/j1_1.stl" scale="0.001 0.001 0.001"/>
      </geometry>
    </collision>
  </link>
  <link name="gripper_1">
    <inertial>
      <origin rpy="0 0 0" xyz="0.0010436911623885672 -0.03676638482013042 0.0011060217486515422"/>
      <mass value="0.9567335515202058"/>
      <inertia ixx="0.000671" ixy="-2e-06" ixz="-1.9e-05" iyy="0.000464" iyz="-8.8e-05" izz="0.000855"/>
    </inertial>
    <visual>
      <origin rpy="0 0 0" xyz="0.0602 0.044866 -0.412995"/>
      <geometry>
        <mesh filename="package://warehouse/meshes/gripper_1.stl" scale="0.001 0.001 0.001"/>
      </geometry>
      <material name="silver"/>
    </visual>
    <collision>
      <origin rpy="0 0 0" xyz="0.0602 0.044866 -0.412995"/>
      <geometry>
        <mesh filename="package://warehouse/meshes/gripper_1.stl" scale="0.001 0.001 0.001"/>
      </geometry>
    </collision>
  </link>
  <joint name="Revolute 4" type="continuous">
    <origin rpy="0 0 0" xyz="-0.034705 0.0 0.059705"/>
    <parent link="j1_1"/>
    <child link="j2_1"/>
    <axis xyz="1.0 0.0 -0.0"/>
  </joint>
  <joint name="Revolute 5" type="continuous">
    <origin rpy="0 0 0" xyz="0.006776 0.0 0.11"/>
    <parent link="j2_1"/>
    <child link="j3_1"/>
    <axis xyz="-1.0 0.0 0.0"/>
  </joint>
  <joint name="Revolute 6" type="continuous">
    <origin rpy="0 0 0" xyz="-0.001444 0.0 0.096"/>
    <parent link="j3_1"/>
    <child link="j4_1"/>
    <axis xyz="1.0 -0.0 -0.0"/>
  </joint>
  <joint name="Revolute 7" type="continuous">
    <origin rpy="0 0 0" xyz="-0.033245 0.0 0.03483"/>
    <parent link="j4_1"/>
    <child link="j5_1"/>
    <axis xyz="0.0 -0.0 1.0"/>
  </joint>
  <joint name="Revolute 9" type="continuous">
    <origin rpy="0 0 0" xyz="0.0 -0.031671 0.039625"/>
    <parent link="j5_1"/>
    <child link="j6_1"/>
    <axis xyz="0.0 1.0 0.0"/>
  </joint>
  <joint name="Revolute 11" type="continuous">
    <origin rpy="0 0 0" xyz="0.002418 0.0 0.072835"/>
    <parent link="base_link"/>
    <child link="j1_1"/>
    <axis xyz="-0.0 0.0 1.0"/>
  </joint>
  <joint name="Rigid 13" type="fixed">
    <origin rpy="0 0 0" xyz="0.0 -0.013195 0.0"/>
    <parent link="j6_1"/>
    <child link="gripper_1"/>
  </joint>
</robot>
