<?xml version='1.0' encoding='utf-8'?>
<sdf version="1.7">
    <model name="joints">
        <link name="shoulder">
            <pose>2.6169476756177256e-17 0.03212256979860132 0.05193842563748254 1.5707963267948968 -1.1102230246251567e-15 -1.9721522630525295e-31</pose>
            <inertial>
                <mass>0.8922359463469776</mass>
                <pose>0.006107302967923395 0.06982017079058637 0.024530497696917654 0.0 0.0 0.0</pose>
                <inertia>
                    <ixx>0.0006369288959821218</ixx>
                    <iyy>0.00024207776340790955</iyy>
                    <izz>0.0007140130108310473</izz>
                    <ixy>-0.00014307807775486953</ixy>
                    <iyz>-1.8278217844192117e-13</iyz>
                    <ixz>2.186477296443956e-13</ixz>
                </inertia>
            </inertial>
            <visual name="shoulder_visual">
                <geometry>
                    <mesh>
                        <uri>model://joints/meshes/shoulder.stl</uri>
                        <scale>0.001 0.001 0.001</scale>
                    </mesh>
                </geometry>
            </visual>
            <collision name="shoulder_collision">
                <geometry>
                    <mesh>
                        <uri>model://joints/meshes/shoulder.stl</uri>
                        <scale>0.001 0.001 0.001</scale>
                    </mesh>
                </geometry>
            </collision>
        </link>
        <link name="elbow1">
            <pose>0.0999999999999995 0.032122569798601217 0.3319384256374826 1.5707963267948966 1.1102230246251567e-15 -3.141592653589793</pose>
            <inertial>
                <mass>1.3454663782767042</mass>
                <pose>0.03594262120968438 -0.13605042786725918 -0.02453049773205564 0.0 0.0 0.0</pose>
                <inertia>
                    <ixx>0.0020138689072998605</ixx>
                    <iyy>0.000380563987445094</iyy>
                    <izz>0.002145662079070922</izz>
                    <ixy>-1.9530435509896662e-12</ixy>
                    <iyz>-3.380131652814983e-16</iyz>
                    <ixz>5.271200143042177e-13</ixz>
                </inertia>
            </inertial>
            <visual name="elbow1_visual">
                <geometry>
                    <mesh>
                        <uri>model://joints/meshes/elbow1.stl</uri>
                        <scale>0.001 0.001 0.001</scale>
                    </mesh>
                </geometry>
            </visual>
            <collision name="elbow1_collision">
                <geometry>
                    <mesh>
                        <uri>model://joints/meshes/elbow1.stl</uri>
                        <scale>0.001 0.001 0.001</scale>
                    </mesh>
                </geometry>
            </collision>
        </link>
        <link name="elbow2">
            <pose>0.04999999999999956 0.032122569798601217 0.5319384256374826 1.5707963267948968 -1.1102230246251567e-15 7.446012809753136e-31</pose>
            <inertial>
                <mass>1.3454663782767038</mass>
                <pose>-0.041927378790315585 -0.23987709453392594 0.02453049770402822 0.0 0.0 0.0</pose>
                <inertia>
                    <ixx>0.0020138689072998067</ixx>
                    <iyy>0.0003805639874451018</iyy>
                    <izz>0.002145662079070826</izz>
                    <ixy>-1.9530398050803476e-12</ixy>
                    <iyz>-3.383128281766478e-16</iyz>
                    <ixz>5.271203260123415e-13</ixz>
                </inertia>
            </inertial>
            <visual name="elbow2_visual">
                <geometry>
                    <mesh>
                        <uri>model://joints/meshes/elbow2.stl</uri>
                        <scale>0.001 0.001 0.001</scale>
                    </mesh>
                </geometry>
            </visual>
            <collision name="elbow2_collision">
                <geometry>
                    <mesh>
                        <uri>model://joints/meshes/elbow2.stl</uri>
                        <scale>0.001 0.001 0.001</scale>
                    </mesh>
                </geometry>
            </collision>
        </link>
        <link name="wrist">
            <pose>0.08999999999999907 0.03212256979860115 0.7069384256374833 -1.5707963267948968 4.912736883966311e-15 3.141592653589793</pose>
            <inertial>
                <mass>0.5621294250304879</mass>
                <pose>0.027530978335849655 0.3571294495835925 0.024530497684512605 0.0 0.0 0.0</pose>
                <inertia>
                    <ixx>0.0001612412753430464</ixx>
                    <iyy>0.00016124127534288533</iyy>
                    <izz>0.00021861826201180468</izz>
                    <ixy>-5.363324269641422e-05</ixy>
                    <iyz>-1.5165078544186918e-13</iyz>
                    <ixz>1.5166848789893818e-13</ixz>
                </inertia>
            </inertial>
            <visual name="wrist_visual">
                <geometry>
                    <mesh>
                        <uri>model://joints/meshes/wrist.stl</uri>
                        <scale>0.001 0.001 0.001</scale>
                    </mesh>
                </geometry>
            </visual>
            <collision name="wrist_collision">
                <geometry>
                    <mesh>
                        <uri>model://joints/meshes/wrist.stl</uri>
                        <scale>0.001 0.001 0.001</scale>
                    </mesh>
                </geometry>
            </collision>
        </link>
        <link name="endeff">
            <pose>0.14999999999999195 0.13212256979860157 0.7819384256374835 3.141592653589787 -9.790680876116187e-14 -1.5265566588598185e-16</pose>
            <inertial>
                <mass>0.8677896590109766</mass>
                <pose>-0.07786999498841096 0.11588371775911781 0.37476166840797953 0.0 0.0 0.0</pose>
                <inertia>
                    <ixx>0.00048065004289465105</ixx>
                    <iyy>0.00026170508204054123</iyy>
                    <izz>0.00039769409462339503</izz>
                    <ixy>2.3478219280241108e-09</ixy>
                    <iyz>-3.828933087831671e-05</iyz>
                    <ixz>7.657905200041939e-09</ixz>
                </inertia>
            </inertial>
            <visual name="endeff_visual">
                <geometry>
                    <mesh>
                        <uri>model://joints/meshes/endeff.stl</uri>
                        <scale>0.001 0.001 0.001</scale>
                    </mesh>
                </geometry>
            </visual>
            <collision name="endeff_collision">
                <geometry>
                    <mesh>
                        <uri>model://joints/meshes/endeff.stl</uri>
                        <scale>0.001 0.001 0.001</scale>
                    </mesh>
                </geometry>
            </collision>
        </link>
        <link name="base_link">
            <pose>0.0 0.0 0.0 0.0 -0.0 0.0</pose>
            <inertial>
                <mass>2.3872115565648064</mass>
                <pose>3.741321866578049e-05 0.0056539776449437305 0.034729694334675335 0.0 0.0 0.0</pose>
                <inertia>
                    <ixx>0.0018634609500875663</ixx>
                    <iyy>0.0017434011436581191</iyy>
                    <izz>0.0016067473199086455</izz>
                    <ixy>1.4751109384342197e-06</ixy>
                    <iyz>-9.467336822800319e-06</iyz>
                    <ixz>1.2099441727078222e-06</ixz>
                </inertia>
            </inertial>
            <visual name="base_link_visual">
                <geometry>
                    <mesh>
                        <uri>model://joints/meshes/base_link.stl</uri>
                        <scale>0.001 0.001 0.001</scale>
                    </mesh>
                </geometry>
            </visual>
            <collision name="base_link_collision">
                <geometry>
                    <mesh>
                        <uri>model://joints/meshes/base_link.stl</uri>
                        <scale>0.001 0.001 0.001</scale>
                    </mesh>
                </geometry>
            </collision>
        </link>
        <link name="Component46-v1">
            <pose>-0.006369915389960821 -0.06192560028352894 0.1564775879476227 7.487161718071197e-15 9.774629160066703e-14 -3.119186265305868</pose>
            <inertial>
                <mass>0.0526959945950827</mass>
                <pose>-0.09279753099437432 -0.20284438659862555 0.25212171777922626 0.0 0.0 0.0</pose>
                <inertia>
                    <ixx>4.693091406404705e-06</ixx>
                    <iyy>2.551126480364682e-06</iyy>
                    <izz>3.680404468285301e-06</izz>
                    <ixy>4.352333646128184e-09</ixy>
                    <iyz>7.244450892489595e-11</iyz>
                    <ixz>9.09739618955739e-09</ixz>
                </inertia>
            </inertial>
            <visual name="Component46-v1_visual">
                <geometry>
                    <mesh>
                        <uri>model://joints/meshes/Component46-v1.stl</uri>
                        <scale>0.001 0.001 0.001</scale>
                    </mesh>
                </geometry>
            </visual>
            <collision name="Component46-v1_collision">
                <geometry>
                    <mesh>
                        <uri>model://joints/meshes/Component46-v1.stl</uri>
                        <scale>0.001 0.001 0.001</scale>
                    </mesh>
                </geometry>
            </collision>
        </link>
        <link name="Component47-v1">
            <pose>0.0177371772401821 -0.0585754949334922 0.15647758794762462 4.275346736850202e-15 9.802718006162554e-14 3.119189637929617</pose>
            <inertial>
                <mass>0.05314846759141695</mass>
                <pose>-0.04015129705556641 -0.2024722925599843 0.25216912717664075 0.0 0.0 0.0</pose>
                <inertia>
                    <ixx>4.722405651580886e-06</ixx>
                    <iyy>2.5686962231235156e-06</iyy>
                    <izz>3.6994040288314606e-06</izz>
                    <ixy>-4.399956275090766e-09</ixy>
                    <iyz>4.3483368758076264e-11</iyz>
                    <ixz>-5.139654567875315e-09</ixz>
                </inertia>
            </inertial>
            <visual name="Component47-v1_visual">
                <geometry>
                    <mesh>
                        <uri>model://joints/meshes/Component47-v1.stl</uri>
                        <scale>0.001 0.001 0.001</scale>
                    </mesh>
                </geometry>
            </visual>
            <collision name="Component47-v1_collision">
                <geometry>
                    <mesh>
                        <uri>model://joints/meshes/Component47-v1.stl</uri>
                        <scale>0.001 0.001 0.001</scale>
                    </mesh>
                </geometry>
            </collision>
        </link>
        <link name="Component49-v1">
            <pose>0.005054838752075113 -0.060358553772483836 0.14797758794762375 6.470194646216449e-15 9.778434408124715e-14 3.141592653589793</pose>
            <inertial>
                <mass>0.7709988590705452</mass>
                <pose>-0.06594447258112864 -0.14698301708561615 0.2673422057526543 0.0 0.0 0.0</pose>
                <inertia>
                    <ixx>0.00033165400163917926</ixx>
                    <iyy>0.00028393168501467103</iyy>
                    <izz>0.0003776081955500167</izz>
                    <ixy>-3.027456343860872e-07</ixy>
                    <iyz>-5.088297655174554e-06</iyz>
                    <ixz>-1.9021060532487307e-05</ixz>
                </inertia>
            </inertial>
            <visual name="Component49-v1_visual">
                <geometry>
                    <mesh>
                        <uri>model://joints/meshes/Component49-v1.stl</uri>
                        <scale>0.001 0.001 0.001</scale>
                    </mesh>
                </geometry>
            </visual>
            <collision name="Component49-v1_collision">
                <geometry>
                    <mesh>
                        <uri>model://joints/meshes/Component49-v1.stl</uri>
                        <scale>0.001 0.001 0.001</scale>
                    </mesh>
                </geometry>
            </collision>
        </link>
        <link name="adapter-v1">
            <pose>0.2005256685268952 0.010876733786437996 0.6858353392153793 3.141592653589787 -9.790680876116188e-14 2.775557561625486e-17</pose>
            <inertial>
                <mass>0.020902045672396473</mass>
                <pose>-0.12839908837610708 -0.04184146412097356 0.2735485681710775 0.0 0.0 0.0</pose>
                <inertia>
                    <ixx>3.013363671764203e-06</ixx>
                    <iyy>5.366568622457419e-06</iyy>
                    <izz>3.016219519577022e-06</izz>
                    <ixy>-2.4007017881129287e-10</ixy>
                    <iyz>1.4896461819207678e-09</iyz>
                    <ixz>6.515444638955721e-13</ixz>
                </inertia>
            </inertial>
            <visual name="adapter-v1_visual">
                <geometry>
                    <mesh>
                        <uri>model://joints/meshes/adapter-v1.stl</uri>
                        <scale>0.001 0.001 0.001</scale>
                    </mesh>
                </geometry>
            </visual>
            <collision name="adapter-v1_collision">
                <geometry>
                    <mesh>
                        <uri>model://joints/meshes/adapter-v1.stl</uri>
                        <scale>0.001 0.001 0.001</scale>
                    </mesh>
                </geometry>
            </collision>
        </link>
        <joint name="base_link_j1" type="revolute">
            <pose>1.7897373471833492e-19 0.023732574362517467 0.024530569798601312 0.0 0.0 0.0</pose>
            <parent>base_link</parent>
            <child>shoulder</child>
            <axis>
                <xyz expressed_in="__model__">0.0 -0.0 1.0</xyz>
            </axis>
        </joint>
        <joint name="shoulder_j2" type="revolute">
            <pose>0.0639349999999998 -0.18413742563748253 -0.024530569798601264 0.0 0.0 0.0</pose>
            <parent>shoulder</parent>
            <child>elbow1</child>
            <axis>
                <xyz expressed_in="__model__">1.0 -0.0 0.0</xyz>
            </axis>
        </joint>
        <joint name="elbow1_j3" type="revolute">
            <pose>-0.013934999999999878 -0.2879634256374826 0.024530569798601277 0.0 0.0 0.0</pose>
            <parent>elbow1</parent>
            <child>elbow2</child>
            <axis>
                <xyz expressed_in="__model__">-1.0 -0.0 0.0</xyz>
            </axis>
        </joint>
        <joint name="elbow2_j4" type="revolute">
            <pose>0.053935000000000954 0.36679042563748326 0.024530569798601215 0.0 0.0 0.0</pose>
            <parent>elbow2</parent>
            <child>wrist</child>
            <axis>
                <xyz expressed_in="__model__">1.0 0.0 0.0</xyz>
            </axis>
        </joint>
        <joint name="wrist_j5" type="revolute">
            <pose>-0.077870000000031 0.12453056979859865 0.40572542563747604 0.0 0.0 0.0</pose>
            <parent>wrist</parent>
            <child>endeff</child>
            <axis>
                <xyz expressed_in="__model__">-0.0 0.0 1.0</xyz>
            </axis>
        </joint>
        <joint name="endeff_j6" type="revolute">
            <pose>-0.12839566852692197 -0.04360026621356376 0.2735573392153665 0.0 0.0 0.0</pose>
            <parent>endeff</parent>
            <child>adapter-v1</child>
            <axis>
                <xyz expressed_in="__model__">0.0 1.0 -0.0</xyz>
            </axis>
        </joint>
        <joint name="adapter-v1_Rigid-16" type="fixed">
            <pose>-0.06707516124795071 -0.11683555377248214 0.26430041205237037 0.0 0.0 0.0</pose>
            <parent>adapter-v1</parent>
            <child>Component49-v1</child>
        </joint>
        <joint name="Component49-v1_Slider-17" type="prismatic">
            <pose>-0.08277861990113215 -0.19004768994505275 0.25225041205237064 0.0 0.0 0.0</pose>
            <parent>Component49-v1</parent>
            <child>Component46-v1</child>
            <axis>
                <xyz expressed_in="__model__">-1.0 0.0 -0.0</xyz>
                <limit>
                    <lower>-0.03</lower>
                    <upper>0.0</upper>
                </limit>
            </axis>
        </joint>
        <joint name="Component49-v1_Slider-18" type="prismatic">
            <pose>-0.05015645768024866 -0.18967565350060994 0.25225041205237125 0.0 0.0 0.0</pose>
            <parent>Component49-v1</parent>
            <child>Component47-v1</child>
            <axis>
                <xyz expressed_in="__model__">-1.0 0.0 -0.0</xyz>
                <limit>
                    <lower>0.0</lower>
                    <upper>0.03</upper>
                </limit>
            </axis>
        </joint>
    </model>
</sdf>