<sdf version='1.9'>
  <world name='car_world'>
    <physics name='1ms' type='ignored'>
      <max_step_size>0.001</max_step_size>
      <real_time_factor>1</real_time_factor>
      <real_time_update_rate>1000</real_time_update_rate>
    </physics>
    <plugin name='ignition::gazebo::systems::Physics' filename='libignition-gazebo-physics-system.so'/>
    <plugin name='ignition::gazebo::systems::UserCommands' filename='libignition-gazebo-user-commands-system.so'/>
    <plugin name='ignition::gazebo::systems::SceneBroadcaster' filename='libignition-gazebo-scene-broadcaster-system.so'/>
    <gravity>0 0 -9.8</gravity>
    <magnetic_field>6e-06 2.3e-05 -4.2e-05</magnetic_field>
    <atmosphere type='adiabatic'/>
    <scene>
      <ambient>0.4 0.4 0.4 1</ambient>
      <background>0.7 0.7 0.7 1</background>
      <shadows>true</shadows>
    </scene>
    <model name='ground_plane'>
      <static>true</static>
      <link name='link'>
        <collision name='collision'>
          <geometry>
            <plane>
              <normal>0 0 1</normal>
              <size>1 1</size>
            </plane>
          </geometry>
          <surface>
            <friction>
              <ode/>
            </friction>
            <bounce/>
            <contact/>
          </surface>
        </collision>
        <visual name='visual'>
          <geometry>
            <plane>
              <normal>0 0 1</normal>
              <size>100 100</size>
            </plane>
          </geometry>
          <material>
            <ambient>0.8 0.8 0.8 1</ambient>
            <diffuse>0.8 0.8 0.8 1</diffuse>
            <specular>0.8 0.8 0.8 1</specular>
          </material>
        </visual>
        <pose>0 0 0 0 -0 0</pose>
        <inertial>
          <pose>0 0 0 0 -0 0</pose>
          <mass>1</mass>
          <inertia>
            <ixx>1</ixx>
            <ixy>0</ixy>
            <ixz>0</ixz>
            <iyy>1</iyy>
            <iyz>0</iyz>
            <izz>1</izz>
          </inertia>
        </inertial>
        <enable_wind>false</enable_wind>
      </link>
      <pose>0 0 0 0 -0 0</pose>
      <self_collide>false</self_collide>
    </model>
    <model name='RaspRover'>
      <link name='Frame'>
        <pose>-0.200286 -0.192087 -0.025303 0 -0 0</pose>
        <inertial>
          <mass>5.5793799999999996</mass>
          <pose>0.200286 -0.183239 -0.061358 0 -0 0</pose>
          <inertia>
            <ixx>0.028476899999999999</ixx>
            <iyy>0.028655799999999999</iyy>
            <izz>0.019928299999999999</izz>
            <ixy>6.4728499999999998e-14</ixy>
            <iyz>-0.00084195600000000004</iyz>
            <ixz>2.1132899999999999e-14</ixz>
          </inertia>
        </inertial>
        <visual name='Frame_visual'>
          <geometry>
            <mesh>
              <uri>file://./meshes/Frame.stl</uri>
              <scale>0.001 0.001 0.001</scale>
            </mesh>
          </geometry>
            <material>
                <ambient>0.2 0.8 0.8 1</ambient>
                <diffuse>0.2 0.8 0.8 1</diffuse>
                <specular>0.5 0.5 0.2 1</specular>
            </material>
        </visual>
        <collision name='Frame_collision'>
          <geometry>
            <mesh>
              <uri>file://./meshes/Frame.stl</uri>
              <scale>0.001 0.001 0.001</scale>
            </mesh>
          </geometry>
        </collision>
        <enable_wind>false</enable_wind>
      </link>
      <link name='Wheel_BR'>
        <pose>0.0554 -0.328775 -0.077992 3.14159 0 0</pose>
        <inertial>
          <mass>0.64435100000000001</mass>
          <pose>-0.130401 0.115194 -0.050131 0 -0 0</pose>
          <inertia>
            <ixx>0.00029685699999999998</ixx>
            <iyy>0.00019567099999999999</iyy>
            <izz>0.000197865</izz>
            <ixy>-3.1298799999999999e-09</ixy>
            <iyz>-6.0852500000000003e-07</iyz>
            <ixz>1.5396000000000001e-08</ixz>
          </inertia>
        </inertial>
        <visual name='Wheel_BR_visual'>
          <geometry>
            <mesh>
              <uri>file://./meshes/Wheel_BR.stl</uri>
              <scale>0.001 0.001 0.001</scale>
            </mesh>
          </geometry>
            <material>
                <ambient>0.0 0.0 0.0 1</ambient>
                <diffuse>0.0 0.0 0.0 1</diffuse>
                <specular>1.0 1.0 1.0 1</specular>
            </material>
        </visual>
        <collision name='Wheel_BR_collision'>
          <geometry>
            <mesh>
              <uri>file://./meshes/Wheel_BR.stl</uri>
              <scale>0.001 0.001 0.001</scale>
            </mesh>
          </geometry>
        </collision>
        <enable_wind>false</enable_wind>
      </link>
      <link name='Wheel_BL'>
        <pose>-0.0746 -0.328775 -0.077992 3.14159 -0 -0</pose>
        <inertial>
          <mass>0.64435100000000001</mass>
          <pose>0.149599 0.115194 -0.050131 0 -0 0</pose>
          <inertia>
            <ixx>0.00029685699999999998</ixx>
            <iyy>0.00019567099999999999</iyy>
            <izz>0.000197865</izz>
            <ixy>-3.1298799999999999e-09</ixy>
            <iyz>-6.0852500000000003e-07</iyz>
            <ixz>1.5396000000000001e-08</ixz>
          </inertia>
        </inertial>
        <visual name='Wheel_BL_visual'>
          <geometry>
            <mesh>
              <uri>file://./meshes/Wheel_BL.stl</uri>
              <scale>0.001 0.001 0.001</scale>
            </mesh>
          </geometry>
            <material>
                <ambient>0.0 0.0 0.0 1</ambient>
                <diffuse>0.0 0.0 0.0 1</diffuse>
                <specular>1.0 1.0 1.0 1</specular>
            </material>
        </visual>
        <collision name='Wheel_BL_collision'>
          <geometry>
            <mesh>
              <uri>file://./meshes/Wheel_BL.stl</uri>
              <scale>0.001 0.001 0.001</scale>
            </mesh>
          </geometry>
        </collision>
        <enable_wind>false</enable_wind>
      </link>
      <link name='Wheel_FR'>
        <pose>0.0554 -0.389575 -0.077992 -3.14159 -0 0</pose>
        <inertial>
          <mass>0.64435100000000001</mass>
          <pose>-0.130401 -0.074806 -0.050131 0 -0 0</pose>
          <inertia>
            <ixx>0.00029685699999999998</ixx>
            <iyy>0.00019567099999999999</iyy>
            <izz>0.000197865</izz>
            <ixy>-3.1298799999999999e-09</ixy>
            <iyz>-6.0852500000000003e-07</iyz>
            <ixz>1.5396000000000001e-08</ixz>
          </inertia>
        </inertial>
        <visual name='Wheel_FR_visual'>
          <geometry>
            <mesh>
              <uri>file://./meshes/Wheel_FR.stl</uri>
              <scale>0.001 0.001 0.001</scale>
            </mesh>
          </geometry>
            <material>
                <ambient>0.0 0.0 0.0 1</ambient>
                <diffuse>0.0 0.0 0.0 1</diffuse>
                <specular>1.0 1.0 1.0 1</specular>
            </material>
        </visual>
        <collision name='Wheel_FR_collision'>
          <geometry>
            <mesh>
              <uri>file://./meshes/Wheel_FR.stl</uri>
              <scale>0.001 0.001 0.001</scale>
            </mesh>
          </geometry>
        </collision>
        <enable_wind>false</enable_wind>
      </link>
      <link name='Wheel_FL'>
        <pose>-0.0746 -0.389575 -0.077992 -3.14159 -0 0</pose>
        <inertial>
          <mass>0.64435100000000001</mass>
          <pose>0.149599 -0.074806 -0.050131 0 -0 0</pose>
          <inertia>
            <ixx>0.00029685699999999998</ixx>
            <iyy>0.00019567099999999999</iyy>
            <izz>0.000197865</izz>
            <ixy>-3.1298799999999999e-09</ixy>
            <iyz>-6.0852500000000003e-07</iyz>
            <ixz>1.5396000000000001e-08</ixz>
          </inertia>
        </inertial>
        <visual name='Wheel_FL_visual'>
          <geometry>
            <mesh>
              <uri>file://./meshes/Wheel_FL.stl</uri>
              <scale>0.001 0.001 0.001</scale>
            </mesh>
          </geometry>
            <material>
                <ambient>0.0 0.0 0.0 1</ambient>
                <diffuse>0.0 0.0 0.0 1</diffuse>
                <specular>1.0 1.0 1.0 1</specular>
            </material>
        </visual>
        <collision name='Wheel_FL_collision'>
          <geometry>
            <mesh>
              <uri>file://./meshes/Wheel_FL.stl</uri>
              <scale>0.001 0.001 0.001</scale>
            </mesh>
          </geometry>
        </collision>
        <enable_wind>false</enable_wind>
      </link>
      <link name='Camera_Pitch'>
        <pose>-0.001603 -0.388495 -0.078208 -3.09531 0 -0.173333</pose>
        <inertial>
          <mass>0.052130599999999999</mass>
          <pose>-0 2e-06 0.200062 0 -0 0</pose>
          <inertia>
            <ixx>2.9160199999999998e-06</ixx>
            <iyy>2.8170899999999998e-06</iyy>
            <izz>3.2214600000000002e-06</izz>
            <ixy>7.4819500000000003e-19</ixy>
            <iyz>-1.7698199999999999e-11</iyz>
            <ixz>-1.4093499999999999e-19</ixz>
          </inertia>
        </inertial>
        <visual name='Camera_Pitch_visual'>
          <geometry>
            <mesh>
              <uri>file://./meshes/Camera_Pitch.stl</uri>
              <scale>0.001 0.001 0.001</scale>
            </mesh>
          </geometry>
            <material>
                <ambient>0.5 0.8 0.2 1</ambient>
                <diffuse>0.5 0.8 0.2 1</diffuse>
                <specular>0.5 0.5 0.5 1</specular>
            </material>
        </visual>
        <collision name='Camera_Pitch_collision'>
          <geometry>
            <mesh>
              <uri>file://./meshes/Camera_Pitch.stl</uri>
              <scale>0.001 0.001 0.001</scale>
            </mesh>
          </geometry>
        </collision>
        <enable_wind>false</enable_wind>
      </link>
      <link name='Camera_Yaw'>
        <pose>0 -0.379335 -0.077992 3.14159 -0 -0.173333</pose>
        <inertial>
          <mass>0.137903</mass>
          <pose>-0 0.000169 0.167551 0 -0 0</pose>
          <inertia>
            <ixx>3.8542599999999999e-05</ixx>
            <iyy>4.3745000000000002e-05</iyy>
            <izz>1.1257799999999999e-05</izz>
            <ixy>-9.9009700000000007e-18</ixy>
            <iyz>-5.5707300000000003e-07</iyz>
            <ixz>5.9203800000000002e-18</ixz>
          </inertia>
        </inertial>
        <visual name='Camera_Yaw_visual'>
          <geometry>
            <mesh>
              <uri>file://./meshes/Camera_Yaw.stl</uri>
              <scale>0.001 0.001 0.001</scale>
            </mesh>
          </geometry>
            <material>
                <ambient>0.1 0.1 0.8 1</ambient>
                <diffuse>0.1 0.1 0.8 1</diffuse>
                <specular>0.5 0.2 0.5 1</specular>
            </material>
        </visual>
        <collision name='Camera_Yaw_collision'>
          <geometry>
            <mesh>
              <uri>file://./meshes/Camera_Yaw.stl</uri>
              <scale>0.001 0.001 0.001</scale>
            </mesh>
          </geometry>
        </collision>
        <enable_wind>false</enable_wind>
      </link>
      <joint name='Frame_Revolute-1' type='revolute'>
        <pose>-0.1154 -0.07484 -0.05 0 -0 0</pose>
        <parent>Frame</parent>
        <child>Wheel_FR</child>
        <axis>
          <xyz>1 0 -0</xyz>
          <limit>
            <lower>-10000000000000000</lower>
            <upper>10000000000000000</upper>
            <effort>20</effort>
            <velocity>20</velocity>
            <stiffness>100000000</stiffness>
            <dissipation>1</dissipation>
          </limit>
          <dynamics>
            <spring_reference>0</spring_reference>
            <spring_stiffness>0</spring_stiffness>
            <damping>0.10000000000000001</damping>
            <friction>0.10000000000000001</friction>
          </dynamics>
        </axis>
      </joint>
      <joint name='Frame_Revolute-2' type='revolute'>
        <pose>0.1346 -0.07484 -0.05 0 -0 0</pose>
        <parent>Frame</parent>
        <child>Wheel_FL</child>
        <axis>
          <xyz>1 0 -0</xyz>
          <limit>
            <lower>-10000000000000000</lower>
            <upper>10000000000000000</upper>
            <effort>20</effort>
            <velocity>20</velocity>
            <stiffness>100000000</stiffness>
            <dissipation>1</dissipation>
          </limit>
          <dynamics>
            <spring_reference>0</spring_reference>
            <spring_stiffness>0</spring_stiffness>
            <damping>0.10000000000000001</damping>
            <friction>0.10000000000000001</friction>
          </dynamics>
        </axis>
      </joint>
      <joint name='Frame_Revolute-3' type='revolute'>
        <pose>0.1346 0.11516 -0.05 0 -0 0</pose>
        <parent>Frame</parent>
        <child>Wheel_BL</child>
        <axis>
          <xyz>1 -0 0</xyz>
          <limit>
            <lower>-10000000000000000</lower>
            <upper>10000000000000000</upper>
            <effort>20</effort>
            <velocity>20</velocity>
            <stiffness>100000000</stiffness>
            <dissipation>1</dissipation>
          </limit>
          <dynamics>
            <spring_reference>0</spring_reference>
            <spring_stiffness>0</spring_stiffness>
            <damping>0.10000000000000001</damping>
            <friction>0.10000000000000001</friction>
          </dynamics>
        </axis>
      </joint>
      <joint name='Frame_Revolute-4' type='revolute'>
        <pose>-0.1154 0.11516 -0.05 0 -0 0</pose>
        <parent>Frame</parent>
        <child>Wheel_BR</child>
        <axis>
          <xyz>1 0 -0</xyz>
          <limit>
            <lower>-10000000000000000</lower>
            <upper>10000000000000000</upper>
            <effort>20</effort>
            <velocity>20</velocity>
            <stiffness>100000000</stiffness>
            <dissipation>1</dissipation>
          </limit>
          <dynamics>
            <spring_reference>0</spring_reference>
            <spring_stiffness>0</spring_stiffness>
            <damping>0.10000000000000001</damping>
            <friction>0.10000000000000001</friction>
          </dynamics>
        </axis>
      </joint>
      <joint name='Frame_Revolute-5' type='revolute'>
        <pose>-0 -0 0.14 0 -0 0</pose>
        <parent>Frame</parent>
        <child>Camera_Yaw</child>
        <axis>
          <xyz>-0 -0 1</xyz>
          <limit>
            <lower>-1.5708</lower>
            <upper>1.5708</upper>
            <effort>inf</effort>
            <velocity>inf</velocity>
            <stiffness>100000000</stiffness>
            <dissipation>1</dissipation>
          </limit>
          <dynamics>
            <spring_reference>0</spring_reference>
            <spring_stiffness>0</spring_stiffness>
            <damping>0</damping>
            <friction>0</friction>
          </dynamics>
        </axis>
      </joint>
      <joint name='Camera_Yaw_Revolute-6' type='revolute'>
        <pose>0.012 -0 0.201 0 -0 0</pose>
        <parent>Camera_Yaw</parent>
        <child>Camera_Pitch</child>
        <axis>
          <xyz>1 -0 0</xyz>
          <limit>
            <lower>-1.0471999999999999</lower>
            <upper>0.52359900000000004</upper>
            <effort>inf</effort>
            <velocity>inf</velocity>
            <stiffness>100000000</stiffness>
            <dissipation>1</dissipation>
          </limit>
          <dynamics>
            <spring_reference>0</spring_reference>
            <spring_stiffness>0</spring_stiffness>
            <damping>0</damping>
            <friction>0</friction>
          </dynamics>
        </axis>
      </joint>
      <plugin name='ignition::gazebo::systems::DiffDrive' filename='libignition-gazebo-diff-drive-system.so'>
        <left_joint>Frame_Revolute-2</left_joint>
        <left_joint>Frame_Revolute-3</left_joint>
        <right_joint>Frame_Revolute-1</right_joint>
        <right_joint>Frame_Revolute-4</right_joint>
        <wheel_separation>0.25</wheel_separation>
        <wheel_radius>0.04</wheel_radius>
        <topic>/cmd_vel</topic>
      </plugin>
      <pose>-0 -5e-06 0.002008 -3.14159 0 -0</pose>
      <static>false</static>
      <self_collide>false</self_collide>
    </model>
    <model name='myCobot_280_PI'>
        <link name='base_link'>
        <inertial>
            <pose>0.002747 0.006582 0.04743 0 -0 0</pose>
            <mass>0.623082</mass>
            <inertia>
            <ixx>0.000684</ixx>
            <ixy>-3e-06</ixy>
            <ixz>3e-06</ixz>
            <iyy>0.000529</iyy>
            <iyz>5e-06</iyz>
            <izz>0.000974</izz>
            </inertia>
        </inertial>
        <collision name='base_link_collision'>
            <pose>0 0 0 0 -0 0</pose>
            <geometry>
            <mesh>
                <scale>0.001 0.001 0.001</scale>
                <uri>file://./meshes/base_link.stl</uri>
            </mesh>
            </geometry>
            <surface>
            <contact>
                <ode/>
            </contact>
            <friction>
                <ode>
                <mu>0.2</mu>
                <mu2>0.2</mu2>
                </ode>
            </friction>
            </surface>
        </collision>
        <visual name='base_link_visual'>
            <pose>0 0 0 0 -0 0</pose>
            <geometry>
            <mesh>
                <scale>0.001 0.001 0.001</scale>
                <uri>file://./meshes/base_link.stl</uri>
            </mesh>
            </geometry>
            <material>
            <script>
                <name>Gazebo/Silver</name>
                <uri>file://media/materials/scripts/gazebo.material</uri>
            </script>
            </material>
        </visual>
        <self_collide>1</self_collide>
        <gravity>1</gravity>
        </link>
        <joint name='Revolute 11' type='revolute'>
        <pose relative_to='base_link'>0.002418 0 0.072835 0 -0 0</pose>
        <parent>base_link</parent>
        <child>j1_1</child>
        <axis>
            <xyz>0 0 1</xyz>
            <limit>
            <lower>-1e+16</lower>
            <upper>1e+16</upper>
            </limit>
            <dynamics>
            <spring_reference>0</spring_reference>
            <spring_stiffness>0</spring_stiffness>
            </dynamics>
        </axis>
        </joint>
        <link name='j1_1'>
        <pose relative_to='Revolute 11'>0 0 0 0 -0 0</pose>
        <inertial>
            <pose>-0.00715 6e-06 0.038268 0 -0 0</pose>
            <mass>0.335581</mass>
            <inertia>
            <ixx>0.000317</ixx>
            <ixy>0</ixy>
            <ixz>5.6e-05</ixz>
            <iyy>0.000357</iyy>
            <iyz>0</iyz>
            <izz>0.000183</izz>
            </inertia>
        </inertial>
        <collision name='j1_1_collision'>
            <pose>-0.002418 0 -0.072835 0 -0 0</pose>
            <geometry>
            <mesh>
                <scale>0.001 0.001 0.001</scale>
                <uri>file://./meshes/j1_1.stl</uri>
            </mesh>
            </geometry>
            <surface>
            <contact>
                <ode/>
            </contact>
            <friction>
                <ode>
                <mu>0.2</mu>
                <mu2>0.2</mu2>
                </ode>
            </friction>
            </surface>
        </collision>
        <visual name='j1_1_visual'>
            <pose>-0.002418 0 -0.072835 0 -0 0</pose>
            <geometry>
            <mesh>
                <scale>0.001 0.001 0.001</scale>
                <uri>file://./meshes/j1_1.stl</uri>
            </mesh>
            </geometry>
            <material>
            <script>
                <name>Gazebo/Silver</name>
                <uri>file://media/materials/scripts/gazebo.material</uri>
            </script>
            </material>
        </visual>
        <self_collide>1</self_collide>
        </link>
        <joint name='Revolute 4' type='revolute'>
        <pose relative_to='j1_1'>-0.034705 0 0.059705 0 -0 0</pose>
        <parent>j1_1</parent>
        <child>j2_1</child>
        <axis>
            <xyz>1 0 0</xyz>
            <limit>
            <lower>-1e+16</lower>
            <upper>1e+16</upper>
            </limit>
            <dynamics>
            <spring_reference>0</spring_reference>
            <spring_stiffness>0</spring_stiffness>
            </dynamics>
        </axis>
        </joint>
        <link name='j2_1'>
        <pose relative_to='Revolute 4'>0 0 0 0 -0 0</pose>
        <inertial>
            <pose>-0.023209 -1e-06 0.051618 0 -0 0</pose>
            <mass>0.524558</mass>
            <inertia>
            <ixx>0.001311</ixx>
            <ixy>0</ixy>
            <ixz>-1e-06</ixz>
            <iyy>0.001359</iyy>
            <iyz>0</iyz>
            <izz>0.000278</izz>
            </inertia>
        </inertial>
        <collision name='j2_1_collision'>
            <pose>0.032287 0 -0.13254 0 -0 0</pose>
            <geometry>
            <mesh>
                <scale>0.001 0.001 0.001</scale>
                <uri>file://./meshes/j2_1.stl</uri>
            </mesh>
            </geometry>
            <surface>
            <contact>
                <ode/>
            </contact>
            <friction>
                <ode>
                <mu>0.2</mu>
                <mu2>0.2</mu2>
                </ode>
            </friction>
            </surface>
        </collision>
        <visual name='j2_1_visual'>
            <pose>0.032287 0 -0.13254 0 -0 0</pose>
            <geometry>
            <mesh>
                <scale>0.001 0.001 0.001</scale>
                <uri>file://./meshes/j2_1.stl</uri>
            </mesh>
            </geometry>
            <material>
            <script>
                <name>Gazebo/Silver</name>
                <uri>file://media/materials/scripts/gazebo.material</uri>
            </script>
            </material>
        </visual>
        <self_collide>1</self_collide>
        </link>
        <joint name='Revolute 5' type='revolute'>
        <pose relative_to='j2_1'>0.006776 0 0.11 0 -0 0</pose>
        <parent>j2_1</parent>
        <child>j3_1</child>
        <axis>
            <xyz>-1 0 0</xyz>
            <limit>
            <lower>-1e+16</lower>
            <upper>1e+16</upper>
            </limit>
            <dynamics>
            <spring_reference>0</spring_reference>
            <spring_stiffness>0</spring_stiffness>
            </dynamics>
        </axis>
        </joint>
        <link name='j3_1'>
        <pose relative_to='Revolute 5'>0 0 0 0 -0 0</pose>
        <inertial>
            <pose>0.02307 0 0.043197 0 -0 0</pose>
            <mass>0.41531</mass>
            <inertia>
            <ixx>0.000783</ixx>
            <ixy>0</ixy>
            <ixz>-3.4e-05</ixz>
            <iyy>0.000834</iyy>
            <iyz>0</iyz>
            <izz>0.000191</izz>
            </inertia>
        </inertial>
        <collision name='j3_1_collision'>
            <pose>0.025511 0 -0.24254 0 -0 0</pose>
            <geometry>
            <mesh>
                <scale>0.001 0.001 0.001</scale>
                <uri>file://./meshes/j3_1.stl</uri>
            </mesh>
            </geometry>
            <surface>
            <contact>
                <ode/>
            </contact>
            <friction>
                <ode>
                <mu>0.2</mu>
                <mu2>0.2</mu2>
                </ode>
            </friction>
            </surface>
        </collision>
        <visual name='j3_1_visual'>
            <pose>0.025511 0 -0.24254 0 -0 0</pose>
            <geometry>
            <mesh>
                <scale>0.001 0.001 0.001</scale>
                <uri>file://./meshes/j3_1.stl</uri>
            </mesh>
            </geometry>
            <material>
            <script>
                <name>Gazebo/Silver</name>
                <uri>file://media/materials/scripts/gazebo.material</uri>
            </script>
            </material>
        </visual>
        <self_collide>1</self_collide>
        </link>
        <joint name='Revolute 6' type='revolute'>
        <pose relative_to='j3_1'>-0.001444 0 0.096 0 -0 0</pose>
        <parent>j3_1</parent>
        <child>j4_1</child>
        <axis>
            <xyz>1 0 0</xyz>
            <limit>
            <lower>-1e+16</lower>
            <upper>1e+16</upper>
            </limit>
            <dynamics>
            <spring_reference>0</spring_reference>
            <spring_stiffness>0</spring_stiffness>
            </dynamics>
        </axis>
        </joint>
        <link name='j4_1'>
        <pose relative_to='Revolute 6'>0 0 0 0 -0 0</pose>
        <inertial>
            <pose>-0.022733 -3e-06 0.007679 0 -0 0</pose>
            <mass>0.189013</mass>
            <inertia>
            <ixx>7.1e-05</ixx>
            <ixy>0</ixy>
            <ixz>1.7e-05</ixz>
            <iyy>9.1e-05</iyy>
            <iyz>0</iyz>
            <izz>6.9e-05</izz>
            </inertia>
        </inertial>
        <collision name='j4_1_collision'>
            <pose>0.026955 0 -0.33854 0 -0 0</pose>
            <geometry>
            <mesh>
                <scale>0.001 0.001 0.001</scale>
                <uri>file://./meshes/j4_1.stl</uri>
            </mesh>
            </geometry>
            <surface>
            <contact>
                <ode/>
            </contact>
            <friction>
                <ode>
                <mu>0.2</mu>
                <mu2>0.2</mu2>
                </ode>
            </friction>
            </surface>
        </collision>
        <visual name='j4_1_visual'>
            <pose>0.026955 0 -0.33854 0 -0 0</pose>
            <geometry>
            <mesh>
                <scale>0.001 0.001 0.001</scale>
                <uri>file://./meshes/j4_1.stl</uri>
            </mesh>
            </geometry>
            <material>
            <script>
                <name>Gazebo/Silver</name>
                <uri>file://media/materials/scripts/gazebo.material</uri>
            </script>
            </material>
        </visual>
        <self_collide>1</self_collide>
        </link>
        <joint name='Revolute 7' type='revolute'>
        <pose relative_to='j4_1'>-0.033245 0 0.03483 0 -0 0</pose>
        <parent>j4_1</parent>
        <child>j5_1</child>
        <axis>
            <xyz>0 0 1</xyz>
            <limit>
            <lower>-1e+16</lower>
            <upper>1e+16</upper>
            </limit>
            <dynamics>
            <spring_reference>0</spring_reference>
            <spring_stiffness>0</spring_stiffness>
            </dynamics>
        </axis>
        </joint>
        <link name='j5_1'>
        <pose relative_to='Revolute 7'>0 0 0 0 -0 0</pose>
        <inertial>
            <pose>-0.000108 -0.002887 0.027643 0 -0 0</pose>
            <mass>0.226476</mass>
            <inertia>
            <ixx>0.000144</ixx>
            <ixy>0</ixy>
            <ixz>1e-06</ixz>
            <iyy>0.00011</iyy>
            <iyz>9e-06</iyz>
            <izz>9.8e-05</izz>
            </inertia>
        </inertial>
        <collision name='j5_1_collision'>
            <pose>0.0602 0 -0.37337 0 -0 0</pose>
            <geometry>
            <mesh>
                <scale>0.001 0.001 0.001</scale>
                <uri>file://./meshes/j5_1.stl</uri>
            </mesh>
            </geometry>
            <surface>
            <contact>
                <ode/>
            </contact>
            <friction>
                <ode>
                <mu>0.2</mu>
                <mu2>0.2</mu2>
                </ode>
            </friction>
            </surface>
        </collision>
        <visual name='j5_1_visual'>
            <pose>0.0602 0 -0.37337 0 -0 0</pose>
            <geometry>
            <mesh>
                <scale>0.001 0.001 0.001</scale>
                <uri>file://./meshes/j5_1.stl</uri>
            </mesh>
            </geometry>
            <material>
            <script>
                <name>Gazebo/Silver</name>
                <uri>file://media/materials/scripts/gazebo.material</uri>
            </script>
            </material>
        </visual>
        <self_collide>1</self_collide>
        </link>
        <joint name='Revolute 9' type='revolute'>
        <pose relative_to='j5_1'>0 -0.031671 0.039625 0 -0 0</pose>
        <parent>j5_1</parent>
        <child>j6_1</child>
        <axis>
            <xyz>0 1 0</xyz>
            <limit>
            <lower>-1e+16</lower>
            <upper>1e+16</upper>
            </limit>
            <dynamics>
            <spring_reference>0</spring_reference>
            <spring_stiffness>0</spring_stiffness>
            </dynamics>
        </axis>
        </joint>
        <link name='j6_1'>
        <pose relative_to='Revolute 9'>0 0 0 0 -0 0</pose>
        <inertial>
            <pose>0.000293 -0.03302 0.000815 0 -0 0</pose>
            <mass>1.06304</mass>
            <inertia>
            <ixx>0.00132754</ixx>
            <ixy>-7.51882e-07</ixy>
            <ixz>-1.61557e-05</ixz>
            <iyy>0.00177849</iyy>
            <iyz>-5.28285e-07</iyz>
            <izz>0.00060916</izz>
            </inertia>
        </inertial>
        <collision name='j6_1_collision'>
            <pose>0.0602 0.031671 -0.412995 0 -0 0</pose>
            <geometry>
            <mesh>
                <scale>0.001 0.001 0.001</scale>
                <uri>file://./meshes/j6_1.stl</uri>
            </mesh>
            </geometry>
            <surface>
            <contact>
                <ode/>
            </contact>
            <friction>
                <ode>
                <mu>0.2</mu>
                <mu2>0.2</mu2>
                </ode>
            </friction>
            </surface>
        </collision>
        <collision name='j6_1_fixed_joint_lump__grip_phone_v1_1_collision_1'>
            <pose>0.0602 0.031671 -0.412995 0 -0 0</pose>
            <geometry>
            <mesh>
                <scale>0.001 0.001 0.001</scale>
                <uri>file://./meshes/grip_phone_v1_1.stl</uri>
            </mesh>
            </geometry>
            <surface>
            <contact>
                <ode/>
            </contact>
            <friction>
                <ode>
                <mu>0.2</mu>
                <mu2>0.2</mu2>
                </ode>
            </friction>
            </surface>
        </collision>
        <collision name='j6_1_fixed_joint_lump__iPhone17_v1_1_collision_2'>
            <pose>0.0602 0.031671 -0.412995 0 -0 0</pose>
            <geometry>
            <mesh>
                <scale>0.001 0.001 0.001</scale>
                <uri>file://./meshes/iPhone17_v1_1.stl</uri>
            </mesh>
            </geometry>
            <surface>
            <contact>
                <ode/>
            </contact>
            <friction>
                <ode>
                <mu>0.2</mu>
                <mu2>0.2</mu2>
                </ode>
            </friction>
            </surface>
        </collision>
        <visual name='j6_1_visual'>
            <pose>0.0602 0.031671 -0.412995 0 -0 0</pose>
            <geometry>
            <mesh>
                <scale>0.001 0.001 0.001</scale>
                <uri>file://./meshes/j6_1.stl</uri>
            </mesh>
            </geometry>
            <material>
            <script>
                <name>Gazebo/Silver</name>
                <uri>file://media/materials/scripts/gazebo.material</uri>
            </script>
            </material>
        </visual>
        <visual name='j6_1_fixed_joint_lump__grip_phone_v1_1_visual_1'>
            <pose>0.0602 0.031671 -0.412995 0 -0 0</pose>
            <geometry>
            <mesh>
                <scale>0.001 0.001 0.001</scale>
                <uri>file://./meshes/grip_phone_v1_1.stl</uri>
            </mesh>
            </geometry>
            <material>
            <script>
                <name>Gazebo/Silver</name>
                <uri>file://media/materials/scripts/gazebo.material</uri>
            </script>
            </material>
        </visual>
        <visual name='j6_1_fixed_joint_lump__iPhone17_v1_1_visual_2'>
            <pose>0.0602 0.031671 -0.412995 0 -0 0</pose>
            <geometry>
            <mesh>
                <scale>0.001 0.001 0.001</scale>
                <uri>file://./meshes/iPhone17_v1_1.stl</uri>
            </mesh>
            </geometry>
            <material>
            <script>
                <name>Gazebo/Silver</name>
                <uri>file://media/materials/scripts/gazebo.material</uri>
            </script>
            </material>
        </visual>
        <self_collide>1</self_collide>
        <self_collide>1</self_collide>
        <self_collide>1</self_collide>
        </link>
    </model>
    <light name='sun' type='directional'>
      <pose>0 0 10 0 -0 0</pose>
      <cast_shadows>true</cast_shadows>
      <intensity>1</intensity>
      <direction>-0.5 0.1 -0.9</direction>
      <diffuse>0.8 0.8 0.8 1</diffuse>
      <specular>0.2 0.2 0.2 1</specular>
      <attenuation>
        <range>1000</range>
        <linear>0.01</linear>
        <constant>0.90000000000000002</constant>
        <quadratic>0.001</quadratic>
      </attenuation>
      <spot>
        <inner_angle>0</inner_angle>
        <outer_angle>0</outer_angle>
        <falloff>0</falloff>
      </spot>
    </light>
  </world>
</sdf>
